Internal Server Error: /tasks/
Traceback (most recent call last):
  File "/home/python/S.R./for_lit/env/lib/python3.5/site-packages/django/core/handlers/exception.py", line 35, in inner
    response = get_response(request)
  File "/home/python/S.R./for_lit/env/lib/python3.5/site-packages/django/core/handlers/base.py", line 128, in _get_response
    response = self.process_exception_by_middleware(e, request)
  File "/home/python/S.R./for_lit/env/lib/python3.5/site-packages/django/core/handlers/base.py", line 126, in _get_response
    response = wrapped_callback(request, *callback_args, **callback_kwargs)
  File "/home/python/S.R./for_lit/L17/dj_test/sess_auth/views.py", line 14, in taskView
    task = Task.object.all()
AttributeError: type object 'Task' has no attribute 'object'
Internal Server Error: /tasks/
Traceback (most recent call last):
  File "/home/python/S.R./for_lit/env/lib/python3.5/site-packages/django/core/handlers/exception.py", line 35, in inner
    response = get_response(request)
  File "/home/python/S.R./for_lit/env/lib/python3.5/site-packages/django/core/handlers/base.py", line 128, in _get_response
    response = self.process_exception_by_middleware(e, request)
  File "/home/python/S.R./for_lit/env/lib/python3.5/site-packages/django/core/handlers/base.py", line 126, in _get_response
    response = wrapped_callback(request, *callback_args, **callback_kwargs)
  File "/home/python/S.R./for_lit/L17/dj_test/sess_auth/views.py", line 15, in taskView
    return JsonResponse(task)
  File "/home/python/S.R./for_lit/env/lib/python3.5/site-packages/django/http/response.py", line 503, in __init__
    'In order to allow non-dict objects to be serialized set the '
TypeError: In order to allow non-dict objects to be serialized set the safe parameter to False.
teeest
